Workbook
Name SegmentaciónDeDatos_Meses__Fecha_de_venta: #N/A

Sheet Detalle1
A1: Detalles de Cuenta de Fecha de venta - Meses (Fecha de venta): Feb
A3: Pedido | B3: Fecha de compra | C3: Fecha llegada | D3: Costo | E3: Costo de envio | F3: Costo total | G3: Modelo | H3: Jugador | I3: Talla | J3: Fecha de venta | K3: Venta | L3: Ganancia
A4: 15 | D4: 12 | E4: 5.7142857 | F4: 17.714286 | G4: Barcelona 2019/20 | J4: 46054 | K4: 39.75 | L4: 22.035714
A5: 15 | D5: 11 | E5: 5.7142857 | F5: 16.714286 | G5: Barcelona 4th | J5: 46054 | K5: 39.75 | L5: 23.035714
A6: 15 | D6: 18 | E6: 5.7142857 | F6: 23.714286 | G6: NFL PATS | J6: 46054 | K6: 39.75 | L6: 16.035714
A7: 15 | D7: 8 | E7: 5.7142857 | F7: 13.714286 | G7: Monterrey Local | J7: 46054 | K7: 39.75 | L7: 26.035714
A8: 15 | D8: 18 | E8: 5.7142857 | F8: 23.714286 | G8: NFL Steelers | J8: 46054 | K8: 39.75 | L8: 16.035714
A9: 15 | D9: 18 | E9: 5.7142857 | F9: 23.714286 | G9: NFL Steelers | J9: 46054 | K9: 39.75 | L9: 16.035714
A10: 15 | D10: 18 | E10: 5.7142857 | F10: 23.714286 | G10: NFL PATS | J10: 46054 | K10: 39.75 | L10: 16.035714

Sheet Detalle2
A1: Detalles de Suma de Costo total - Meses (Fecha de venta): Oct
A3: Pedido | B3: Fecha de compra | C3: Fecha llegada | D3: Costo | E3: Costo de envio | F3: Costo total | G3: Modelo | H3: Jugador | I3: Talla | J3: Fecha de venta | K3: Venta | L3: Ganancia
A4: 9 | B4: 45920 | C4: 45942 | D4: 10.5 | E4: 4.37 | F4: 16.25 | G4: Barcelona POLO | I4: L | J4: 45945 | K4: 26.89 | L4: 10.64
A5: 9 | B5: 45920 | C5: 45942 | D5: 11.88 | E5: 4.37 | F5: 14.87 | G5: NFL GreenBay | H5: Rodgers | I5: L | J5: 45945 | K5: 37.64 | L5: 22.77
A6: 9 | B6: 45920 | C6: 45942 | D6: 11.88 | E6: 4.37 | F6: 16.87 | G6: NFL 49ers | H6: Purdy | I6: L | J6: 45945 | K6: 37.64 | L6: 20.77
A7: 9 | B7: 45920 | C7: 45942 | D7: 11.88 | E7: 4.37 | F7: 16.87 | G7: NFL Steelers | H7: Rodgers | I7: L | J7: 45945 | K7: 37.64 | L7: 20.77
A8: 9 | B8: 45920 | C8: 45942 | D8: 10.5 | E8: 4.37 | F8: 14.87 | G8: Cruz azul visitante 25/26 | I8: 2XL | J8: 45953 | K8: 26.89 | L8: 12.02
A9: 9 | B9: 45920 | C9: 45942 | D9: 12.5 | E9: 4.37 | F9: 16.25 | G9: Real Madrid Alternativa 25-26 Version jugador | I9: M | J9: 45961 | K9: 32.17 | L9: 15.92
A10: 9 | B10: 45920 | C10: 45942 | D10: 12.5 | E10: 4.37 | F10: 16.25 | G10: Real Madrid Alternativa 25-26 Version jugador | I10: L | J10: 45961 | K10: 32.17 | L10: 15.92
A11: 8 | B11: 45910 | D11: 22.33 | E11: 0 | F11: 12.91 | G11: America visitante mujer | I11: M | J11: 45942 | K11: 29.88 | L11: 16.97
A12: 8 | B12: 45910 | D12: 8.8 | E12: 4.11 | F12: 12.91 | G12: Portugal | I12: M | J12: 45945 | K12: 37 | L12: 24.09
A13: 8 | B13: 45910 | D13: 8.8 | E13: 4.11 | F13: 12.91 | G13: Argentina 25/26 | I13: M | J13: 45945 | K13: 37 | L13: 24.09
A14: 8 | B14: 45910 | D14: 8.8 | E14: 4.11 | F14: 12.91 | G14: Barcelona tercera equipacion | I14: L | J14: 45946 | K14: 29.88 | L14: 16.97
A15: 8 | B15: 45910 | D15: 8.8 | E15: 4.11 | F15: 12.91 | G15: Brazil Total 90 | I15: L | J15: 45959 | K15: 40.36 | L15: 27.45
A16: 8 | B16: 45910 | D16: 8.8 | E16: 4.11 | F16: 12.91 | G16: Holanda Total 90 | I16: XL | J16: 45961 | K16: 27.17 | L16: 14.26
A17: 7 | B17: 45897 | D17: 10 | E17: 5.33 | F17: 15.83 | G17: FC Barcelona Travis scott | I17: L | J17: 45951 | K17: 32.51 | L17: 16.68
A18: 7 | B18: 45897 | D18: 11.5 | E18: 5.33 | F18: 16.83 | G18: Real Madrid Alternativa 25-26 Version jugador | H18: MBAPPE | I18: M | J18: 45942 | K18: 32.5 | L18: 15.67
A19: 7 | B19: 45897 | D19: 11.5 | E19: 5.33 | F19: 15.33 | G19: Real Madrid Alternativa 25-26 Version jugador | H19: MBAPPE | I19: XL | J19: 45951 | K19: 35.22 | L19: 19.89
A20: 6 | B20: 45892 | C20: 45908 | D20: 10.5 | E20: 6.25 | F20: 16.75 | G20: Real Madrid 25-26 Version jugador | H20: MBAPPE | I20: XL | J20: 45951 | K20: 35.42 | L20: 18.67
A21: 5 | B21: 45887 | C21: 45914 | D21: 15 | E21: 4.11 | F21: 15.11 | G21: NFL Seahawks | I21: 3xl | J21: 45931 | K21: 31.97 | L21: 16.86
A22: 5 | B22: 45887 | C22: 45914 | D22: 10.5 | E22: 4.11 | F22: 15.11 | G22: Cruz Azul local 25/26 | I22: XL | J22: 45933 | K22: 27.22 | L22: 12.11
A23: 3 | B23: 45849 | C23: 45881 | D23: 12 | E23: 5.92 | F23: 16.42 | G23: Real Madrid 25-26 Version jugador | H23: VINI JR | I23: XL | J23: 45942 | K23: 32.97 | L23: 16.55
A24: 3 | B24: 45849 | C24: 45881 | D24: 9 | E24: 5.92 | F24: 14.92 | G24: Cruz azul visitante 25/26 | I24: M | J24: 45931 | K24: 27.22 | L24: 12.3
A25: 5 | B25: 45887 | C25: 45914 | D25: 10.5 | E25: 4.11 | F25: 14.61 | G25: FC Barcelona Travis scott | I25: L | J25: 45946 | K25: 32.51 | L25: 17.9
A26: 5 | B26: 45887 | C26: 45914 | D26: 10.5 | E26: 4.11 | F26: 15.11 | G26: Cruz Azul local 25/26 | I26: L | J26: 45961 | K26: 29.62 | L26: 14.51
A27: 5 | B27: 45887 | C27: 45908 | D27: 11 | E27: 4.11 | F27: 14.61 | G27: Real Madrid Alternativa 25-26 Version jugador | H27: MBAPPE | I27: M | J27: 45942 | K27: 32.27 | L27: 17.66
A28: 5 | B28: 45887 | C28: 45908 | D28: 11 | E28: 4.11 | F28: 14.61 | G28: Real Madrid Alternativa 25-26 Version jugador | H28: MBAPPE | I28: L | J28: 45951 | K28: 35.22 | L28: 20.61
A29: 3 | B29: 45849 | C29: 45872 | D29: 11 | E29: 5.92 | F29: 17.92 | G29: Conjunto Real Madrid nni–o | H29: MBAPPƒ | I29: 28 | J29: 45936 | K29: 24.46 | L29: 6.54
A30: 5 | B30: 45887 | C30: 45908 | D30: 11 | E30: 4.11 | F30: 14.61 | G30: Real Madrid Alternativa 25-26 Version jugador | H30: MBAPPE | I30: L | J30: 45951 | K30: 35.22 | L30: 20.61
A31: 3 | B31: 45849 | C31: 45872 | D31: 8 | E31: 5.92 | F31: 14.92 | G31: Conjunto Chicago bulls | H31: JORDAN | I31: L | J31: 45943 | K31: 21.66 | L31: 6.74
A32: 3 | B32: 45849 | C32: 45872 | D32: 8 | E32: 5.92 | F32: 16.92 | G32: Conjunto Golden state | H32: CURRY | I32: L | J32: 45943 | K32: 21.66 | L32: 4.74
A33: 3 | B33: 45849 | C33: 45872 | D33: 8 | E33: 5.92 | F33: 13.92 | G33: Conjunto Lakers | H33: JAMES | I33: XL | J33: 45943 | K33: 21.66 | L33: 7.74
A34: 3 | B34: 45849 | C34: 45872 | D34: 10.65 | E34: 5.92 | F34: 16.42 | G34: Conjunto inter miami ni–o | H34: MESSI | I34: 22 | J34: 45949 | K34: 21.67 | L34: 5.25
A35: 4 | F35: 15.83 | G35: FC Barcelona visitante 25/26 | H35: LAMINE YAMAL | I35: S | J35: 45943 | K35: 37.91 | L35: 22.08

Sheet Detalle3
A1: Detalles de Suma de Costo total - Meses (Fecha de compra): <6/12/2025
A3: Pedido | B3: Fecha de compra | C3: Fecha llegada | D3: Costo | E3: Costo de envio | F3: Costo total | G3: Modelo | H3: Jugador | I3: Talla | J3: Fecha de venta | K3: Venta | L3: Ganancia
A4: 18
A5: 17 | F5: 11.19 | G5: Rayados visita | I5: L | J5: 46054 | K5: 34.81 | L5: 23.62
A6: 17 | F6: 11.19 | G6: Rayados Local | I6: L | J6: 46054 | K6: 29.01 | L6: 17.82
A7: 16 | F7: 11.19 | G7: Chivas | I7: L | J7: 46059 | K7: 31.66 | L7: 20.47
A8: 16 | F8: 11.19 | G8: Chivas | I8: M | J8: 46058 | K8: 31.66 | L8: 20.47
A9: 15 | D9: 12 | E9: 5.7142857 | F9: 17.714286 | G9: Barcelona 2019/20 | J9: 46054 | K9: 39.75 | L9: 22.035714
A10: 15 | D10: 11 | E10: 5.7142857 | F10: 16.714286 | G10: Barcelona 4th | J10: 46054 | K10: 39.75 | L10: 23.035714
A11: 15 | D11: 8 | E11: 5.7142857 | F11: 13.714286 | G11: Barcelona 4th | L11: -13.714286
A12: 15 | D12: 8 | E12: 5.7142857 | F12: 13.714286 | G12: Barcelona 4th | L12: -13.714286
A13: 15 | D13: 6 | E13: 5.7142857 | F13: 11.714286 | G13: Barcelona 4th | L13: -11.714286
A14: 15 | D14: 6 | E14: 5.7142857 | F14: 11.714286 | G14: MEXICO | I14: L | L14: -11.714286
A15: 15 | D15: 6 | E15: 5.7142857 | F15: 11.714286 | G15: MEXICO | I15: L | L15: -11.714286
A16: 15 | D16: 6 | E16: 5.7142857 | F16: 11.714286 | G16: MEXICO | I16: L | L16: -11.714286
A17: 15 | D17: 18 | E17: 5.7142857 | F17: 23.714286 | G17: NFL pats | J17: 46054 | K17: 39.75 | L17: 16.035714
A18: 15 | D18: 8 | E18: 5.7142857 | F18: 13.714286 | G18: Monterrey Local | J18: 46054 | K18: 39.75 | L18: 26.035714
A19: 15 | D19: 18 | E19: 5.7142857 | F19: 23.714286 | G19: NFL Steelers | J19: 46054 | K19: 39.75 | L19: 16.035714
A20: 15 | D20: 18 | E20: 5.7142857 | F20: 23.714286 | G20: NFL Steelers | J20: 46054 | K20: 39.75 | L20: 16.035714
A21: 15 | D21: 18 | E21: 5.7142857 | F21: 23.714286 | G21: NFL PATS | J21: 46054 | K21: 39.75 | L21: 16.035714
A22: 14 | D22: 6 | E22: 6.1178571 | F22: 12.117857 | G22: CHIVAS | I22: XXL | J22: 46065 | K22: 29.1 | L22: 16.982143
A23: 14 | D23: 6 | E23: 6.1178571 | F23: 12.117857 | G23: CHIVAS | I23: M | J23: 46048 | K23: 31.66 | L23: 19.542143
A24: 14 | D24: 6 | E24: 6.1178571 | F24: 12.117857 | G24: TIGRES | I24: XL | L24: -12.117857
A25: 14 | D25: 6 | E25: 6.1178571 | F25: 12.117857 | G25: TIGRES | I25: L | L25: -12.117857
A26: 14 | D26: 6 | E26: 6.1178571 | F26: 12.117857 | G26: TIGRES | I26: M | L26: -12.117857
A27: 14 | D27: 6 | E27: 6.1178571 | F27: 12.117857 | G27: Monterrey Local | I27: XL | L27: -12.117857
A28: 14 | D28: 6 | E28: 6.1178571 | F28: 12.117857 | G28: Monterrey Local | I28: L | J28: 46053 | K28: 31.66 | L28: 19.542143
A29: 14 | D29: 6 | E29: 6.1178571 | F29: 12.117857 | G29: Monterrey Local | I29: M | L29: -12.117857
A30: 14 | D30: 6 | E30: 6.1178571 | F30: 12.117857 | G30: America 25-26 Version jugador | I30: XXL | J30: 46064 | K30: 34.92 | L30: 22.802143
A31: 14 | D31: 6 | E31: 6.1178571 | F31: 12.117857 | G31: America 25-26 Version jugador | I31: XL | J31: 46055 | K31: 0 | L31: -12.117857
A32: 14 | D32: 6 | E32: 6.1178571 | F32: 12.117857 | G32: America 25-26 Version jugador | I32: L | J32: 46054 | K32: 0 | L32: -12.117857
A33: 14 | D33: 6 | E33: 6.1178571 | F33: 12.117857 | G33: America 25-26 Version jugador | I33: M | J33: 46059 | K33: 31.49 | L33: 19.372143
A34: 14 | D34: 8 | E34: 6.1178571 | F34: 14.117857 | G34: MEXICO | I34: XXL | L34: -14.117857
A35: 14 | D35: 8 | E35: 6.1178571 | F35: 14.117857 | G35: MEXICO | I35: XL | L35: -14.117857
A36: 14 | D36: 8 | E36: 6.1178571 | F36: 14.117857 | G36: MEXICO | I36: M | L36: -14.117857
A37: 14 | D37: 8 | E37: 6.1178571 | F37: 14.117857 | G37: CRUZ AZUL ALTERNATIVA | I37: XXL | J37: 46053 | K37: 31.58 | L37: 17.462143
A38: 14 | D38: 8 | E38: 6.1178571 | F38: 14.117857 | G38: CRUZ AZUL ALTERNATIVA | I38: XL | J38: 46051 | K38: 27.59 | L38: 13.472143
A39: 14 | D39: 8 | E39: 6.1178571 | F39: 14.117857 | G39: CRUZ AZUL ALTERNATIVA | I39: XL | J39: 46051 | K39: 27.59 | L39: 13.472143
A40: 14 | D40: 8 | E40: 6.1178571 | F40: 14.117857 | G40: CRUZ AZUL ALTERNATIVA | I40: L | J40: 46053 | K40: 28.63 | L40: 14.512143
A41: 14 | D41: 8 | E41: 6.1178571 | F41: 14.117857 | G41: CRUZ AZUL ALTERNATIVA | I41: L | J41: 46051 | K41: 27.59 | L41: 13.472143
...

Sheet Detalle4
A1: Detalles de Ventas por mes - Meses (Fecha de venta): Feb
A3: Pedido | B3: Fecha de compra | C3: Fecha llegada | D3: Costo | E3: Costo de envio | F3: Costo total | G3: Modelo | H3: Jugador | I3: Talla | J3: Fecha de venta | K3: Venta | L3: Ganancia
A4: 17 | B4: 46058 | F4: 11.19 | G4: Rayados visita | I4: L | J4: 46054 | K4: 34.81 | L4: 23.62
A5: 17 | B5: 46058 | F5: 11.19 | G5: Rayados Local | I5: L | J5: 46054 | K5: 29.01 | L5: 17.82
A6: 16 | B6: 46053 | F6: 11.19 | G6: CHIVAS | I6: L | J6: 46059 | K6: 31.66 | L6: 20.47
A7: 16 | B7: 46053 | F7: 11.19 | G7: CHIVAS | I7: M | J7: 46058 | K7: 31.66 | L7: 20.47
A8: 15 | B8: 46040 | D8: 12 | E8: 5.7142857 | F8: 17.714286 | G8: Barcelona 2019/20 | J8: 46054 | K8: 39.75 | L8: 22.035714
A9: 15 | B9: 46040 | D9: 11 | E9: 5.7142857 | F9: 16.714286 | G9: Barcelona 4th | J9: 46054 | K9: 39.75 | L9: 23.035714
A10: 15 | B10: 46040 | D10: 8 | E10: 5.7142857 | F10: 13.714286 | G10: Monterrey Local | I10: L | J10: 46054 | K10: 39.75 | L10: 26.035714
A11: 15 | B11: 46040 | D11: 18 | E11: 5.7142857 | F11: 23.714286 | G11: NFL Steelers | J11: 46054 | K11: 39.75 | L11: 16.035714
A12: 15 | B12: 46040 | D12: 18 | E12: 5.7142857 | F12: 23.714286 | G12: NFL Steelers | J12: 46054 | K12: 39.75 | L12: 16.035714
A13: 15 | B13: 46040 | D13: 18 | E13: 5.7142857 | F13: 23.714286 | G13: NFL PATS | J13: 46054 | K13: 39.75 | L13: 16.035714
A14: 14 | B14: 46022 | D14: 6 | E14: 6.1178571 | F14: 12.117857 | G14: CHIVAS | I14: XXL | J14: 46065 | K14: 29.1 | L14: 16.982143
A15: 14 | B15: 46022 | D15: 6 | E15: 6.1178571 | F15: 12.117857 | G15: Monterrey Local | I15: XL | J15: 46071 | K15: 39.75 | L15: 27.632143
A16: 14 | B16: 46022 | D16: 6 | E16: 6.1178571 | F16: 12.117857 | G16: Monterrey Local | I16: M | J16: 46066 | K16: 29.18 | L16: -12.117857
A17: 14 | B17: 46022 | D17: 6 | E17: 6.1178571 | F17: 12.117857 | G17: America 25-26 Version jugador | I17: XXL | J17: 46064 | K17: 34.92 | L17: 22.802143
A18: 14 | B18: 46022 | D18: 6 | E18: 6.1178571 | F18: 12.117857 | G18: America 25-26 Version jugador | I18: XL | J18: 46055 | K18: 0 | L18: -12.117857
A19: 14 | B19: 46022 | D19: 6 | E19: 6.1178571 | F19: 12.117857 | G19: America 25-26 Version jugador | I19: L | J19: 46054 | K19: 0 | L19: -12.117857
A20: 14 | B20: 46022 | D20: 6 | E20: 6.1178571 | F20: 12.117857 | G20: America 25-26 Version jugador | I20: M | J20: 46059 | K20: 31.49 | L20: 19.372143
A21: 14 | B21: 46022 | D21: 8 | E21: 6.1178571 | F21: 14.117857 | G21: Cruz azul local 25/26 | I21: XXL | J21: 46072 | K21: 32.1 | L21: 17.982143
A22: 14 | B22: 46022 | D22: 8 | E22: 6.1178571 | F22: 14.117857 | G22: Cruz azul local 25/26 | I22: XXL | J22: 46074 | K22: 32.1 | L22: 17.982143
A23: 14 | B23: 46022 | D23: 8 | E23: 6.1178571 | F23: 14.117857 | G23: Cruz azul local 25/26 | I23: XL | J23: 46074 | K23: 32.1 | L23: 17.982143
A24: 14 | B24: 46022 | D24: 8 | E24: 6.1178571 | F24: 14.117857 | G24: Cruz azul local 25/26 | I24: M | J24: 46059 | K24: 31.82 | L24: 17.702143

Sheet Hoja3
A3: Etiquetas de fila | B3: Total Ganancia por mes | C3: Ganancia promedio por jersey | D3: Total venta | E3: Ventas por mes | I3: PROMEDIO GANANCIA MENSUAL
A4: Jan | B4: 392.01236 | C4: 17.044016 | D4: 721.39 | E4: 23 | I4: =AVERAGE(B4:B11) -> 341.64155
A5: Feb | B5: 404.35 | C5: 16.847917 | D5: 753.93 | E5: 24
A6: Jul | B6: 200.17 | C6: 20.017 | D6: 364.67 | E6: 10
A7: Aug | B7: 226.75 | C7: 14.171875 | D7: 471.85 | E7: 16
A8: Sep | B8: 456.92 | C8: 16.318571 | D8: 861.04 | E8: 28
A9: Oct | B9: 515.75 | C9: 16.117187 | D9: 1001.22 | E9: 32 | I9: TOTAL GANANCIAS
A10: Nov | B10: 432.81 | C10: 16.646538 | D10: 863.08 | E10: 26 | I10: =GETPIVOTDATA("Total venta",$A$3)-GETPIVOTDATA("Total Ganancia por mes",$A$3) -> 2504.7376
A11: Dec | B11: 104.37 | C11: 14.91 | D11: 200.69 | E11: 7
A12: Total general | B12: 2733.1324 | C12: 16.464653 | D12: 5237.87 | E12: 166
I14: TOTAL COSTOS EXISTENCIAS
I15: =SUMIF('Tabla jerseys'!K2:K192, "", 'Tabla jerseys'!F2:F192) -> 336.41808
A16: Etiquetas de fila | B16: Costo jerseys por mes | C16: Jerseys comprados
A17: Jan | B17: 239.66571 | C17: 15
A18: Feb | B18: 97.68 | C18: 7
A19: Jun | B19: 165 | C19: 10
A20: Jul | B20: 566.75 | C20: 36
A21: Aug | B21: 619.65 | C21: 42
A22: Sep | B22: 354.03 | C22: 25
A23: Oct | B23: 272.41 | C23: 15
A24: Dec | B24: 562.3 | C24: 41
A25: Total general | B25: 2877.4857 | C25: 191
B30: Etiquetas de columna
A31: Etiquetas de fila | B31: Jan | C31: Feb | D31: Jun | E31: Jul | F31: Aug | G31: Sep | H31: Oct | I31: Dec | J31: Total general
A32: <1/19/2025
A33: Jan
A34: Feb
A35: Jul
A36: Aug
A37: 45873
A38: FC Barcelona 25-26 Version jugador
A39: 45840
A40: 45874
A41: Conjunto Golden state
A42: 45849
A43: 45875
A44: FC Barcelona 25-26 Version jugador
A45: 45840
A46: 45877
A47: Chelsea 2025/26
...

Sheet Tabla jerseys
A1: Pedido | B1: Fecha de compra | C1: Fecha llegada | D1: Costo | E1: Costo de envio | F1: Costo total | G1: Modelo | H1: Jugador | I1: Talla | J1: Fecha de venta | K1: Venta | L1: Ganancia
A2: 1 | B2: 45820 | C2: 45841 | D2: 10 | E2: 5 | F2: ='Tabla jerseys'!$D2+'Tabla jerseys'!$E2 -> 15 | G2: FC Barcelona 25-26 Version jugador | I2: M | J2: 45853 | K2: 26.87 | L2: =K2-F2 -> 11.87
A3: 1 | B3: 45820 | C3: 45841 | D3: 10.5 | E3: 6 | F3: ='Tabla jerseys'!$D3+'Tabla jerseys'!$E3 -> 16.5 | G3: Real Madrid 25-26 Version jugador | I3: M | J3: 45848 | K3: 26.87 | L3: =K3-F3 -> 10.37
A4: 1 | B4: 45820 | C4: 45841 | D4: 10.5 | E4: 6 | F4: ='Tabla jerseys'!$D4+'Tabla jerseys'!$E4 -> 16.5 | G4: FC Barcelona 25-26 Version jugador | I4: XL | J4: 45846 | K4: 29.55 | L4: =K4-F4 -> 13.05
A5: 1 | B5: 45820 | C5: 45841 | D5: 10.5 | E5: 6 | F5: ='Tabla jerseys'!$D5+'Tabla jerseys'!$E5 -> 16.5 | G5: Real Madrid 25-26 Version jugador | H5: MBAPPE | I5: L | J5: 45845 | K5: 37.6 | L5: =K5-F5 -> 21.1 | N5: Total jerseys | O5: =COUNT($L$2:$L$192) -> 191
A6: 1 | B6: 45820 | C6: 45841 | D6: 10.5 | E6: 6 | F6: ='Tabla jerseys'!$D6+'Tabla jerseys'!$E6 -> 16.5 | G6: FC Barcelona 25-26 Version jugador | H6: PEDRI | I6: L | J6: 45844 | K6: 37.57 | L6: =K6-F6 -> 21.07 | N6: Jersey Vedidas | O6: =COUNTIF($L$2:$L$192,">0") -> 164
A7: 1 | B7: 45820 | C7: 45841 | D7: 10.5 | E7: 6 | F7: ='Tabla jerseys'!$D7+'Tabla jerseys'!$E7 -> 16.5 | G7: Real Madrid 25-26 Version jugador | I7: XL | J7: 45843 | K7: 32.2 | L7: =K7-F7 -> 15.7 | N7: Jersey disponible | O7: =COUNTIF($L$2:$L$192,"<0") -> 27
A8: 1 | B8: 45820 | C8: 45841 | D8: 11 | E8: 6 | F8: ='Tabla jerseys'!$D8+'Tabla jerseys'!$E8 -> 17 | G8: FC Barcelona 25-26 Version jugador | H8: LAMINE YAMAL | I8: L | J8: 45841 | K8: 48.19 | L8: =K8-F8 -> 31.19 | N8: Total Costo | O8: =SUM($F$2:$F$192) -> 2877.4857
A9: 1 | B9: 45820 | C9: 45841 | D9: 11 | E9: 6 | F9: ='Tabla jerseys'!$D9+'Tabla jerseys'!$E9 -> 17 | G9: FC Barcelona 25-26 Version jugador | H9: LAMINE YAMAL | I9: L | J9: 45841 | K9: 48.19 | L9: =K9-F9 -> 31.19 | N9: Total venta | O9: =SUM($K$2:$K$192) -> 5246.07
A10: 1 | B10: 45820 | C10: 45841 | D10: 10.5 | E10: 6 | F10: ='Tabla jerseys'!$D10+'Tabla jerseys'!$E10 -> 16.5 | G10: Real Madrid 25-26 Version jugador | H10: MBAPPE | I10: L | J10: 45841 | K10: 40 | L10: =K10-F10 -> 23.5 | N10: Ganancia | O10: =O9-O8 -> 2368.5843
A11: 1 | B11: 45820 | C11: 45841 | D11: 11 | E11: 6 | F11: ='Tabla jerseys'!$D11+'Tabla jerseys'!$E11 -> 17 | G11: Real Madrid 25-26 Version jugador | H11: VINI JR | I11: L | L11: =K11-F11 -> -17 | N11: Total Costo de disponibles | O11: =SUMIF('Tabla jerseys'!$L$2:$L$192,"<0",'Tabla jerseys'!$F$2:$F$192) -> 379.48379
A12: 2 | B12: 45840 | C12: 45860 | D12: 11 | E12: 6 | F12: ='Tabla jerseys'!$D16+'Tabla jerseys'!$E16 -> 17 | G12: FC Barcelona 25-26 Version jugador | H12: LAMINE YAMAL | I12: L | J12: 45967 | K12: 29.58 | L12: =K12-F12 -> 12.58 | N12: Ganancia promedio por jersey vendida | O12: =AVERAGEIF($L$2:$L$192,">0",$L$2:$L$192) -> 16.81322
A13: 2 | B13: 45840 | C13: 45860 | D13: 11 | E13: 6 | F13: ='Tabla jerseys'!$D12+'Tabla jerseys'!$E12 -> 17 | G13: FC Barcelona 25-26 Version jugador | H13: LAMINE YAMAL | I13: Xl | J13: 45903 | K13: 32.2 | L13: =K13-F13 -> 15.2 | N13: Ganancia esperada total | O13: =O12*O5 -> 3211.325
A14: 2 | B14: 45840 | C14: 45860 | D14: 10.5 | E14: 6 | F14: ='Tabla jerseys'!$D13+'Tabla jerseys'!$E13 -> 17 | G14: FC Barcelona 25-26 Version jugador | H14: LAMINE YAMAL | I14: L | J14: 45875 | K14: 32.25 | L14: =K14-F14 -> 15.25 | N14: Ganancia por ganar | O14: =O12*O7 -> 453.95694
A15: 2 | B15: 45840 | C15: 45860 | D15: 10.5 | E15: 6 | F15: ='Tabla jerseys'!$D14+'Tabla jerseys'!$E14 -> 16.5 | G15: FC Barcelona 25-26 Version jugador | H15: LAMINE YAMAL | I15: L | J15: 45873 | K15: 32.25 | L15: =K15-F15 -> 15.75 | N15: Ventas por jersey apartadas | O15: =SUMIF('Tabla jerseys'!$J$2:$J$114,"",'Tabla jerseys'!$K$2:$K$114) -> 0
A16: 2 | B16: 45840 | C16: 45860 | D16: 11 | E16: 6 | F16: ='Tabla jerseys'!$D15+'Tabla jerseys'!$E15 -> 16.5 | G16: FC Barcelona 25-26 Version jugador | H16: LAMINE YAMAL | I16: M | J16: 45862 | K16: 37.63 | L16: =K16-F16 -> 21.13 | N16: Ganancia por jersey apartada | O16: =O18+SUMIFS('Tabla jerseys'!$L$2:$L$114,'Tabla jerseys'!$L$2:$L$114,">0",'Tabla jerseys'!$J$2:$J$114,"") -> 0
A17: 3 | B17: 45849 | C17: 45881 | D17: 9 | E17: 5.92 | F17: ='Tabla jerseys'!$D43+'Tabla jerseys'!$E43 -> 16.42 | G17: FC Barcelona 25-26 version jugador | H17: Pedri | I17: L | J17: 45992 | K17: 30.05 | L17: =K17-F17 -> 13.63
A18: 3 | B18: 45849 | C18: 45881 | D18: 11 | E18: 5.92 | F18: ='Tabla jerseys'!$D47+'Tabla jerseys'!$E47 -> 14.92 | G18: Monterrey mundial version jugador | H18: Sergio Ramos | I18: XL | J18: 45980 | K18: 32.69 | L18: =K18-F18 -> 17.77
A19: 3 | B19: 45849 | C19: 45881 | D19: 8 | E19: 5.92 | F19: ='Tabla jerseys'!$D40+'Tabla jerseys'!$E40 -> 17.92 | G19: FC Barcelona parche | I19: S | J19: 45971 | K19: 32.52 | L19: =K19-F19 -> 14.6
A20: 3 | B20: 45849 | C20: 45881 | D20: 10.5 | E20: 5.92 | F20: ='Tabla jerseys'!$D39+'Tabla jerseys'!$E39 -> 15.92 | G20: Conjunto Golden state | H20: CURRY | I20: XL | J20: 45874 | K20: 32.25 | L20: =K20-F20 -> 16.33
A21: 3 | B21: 45849 | C21: 45881 | D21: 12 | E21: 5.92 | F21: ='Tabla jerseys'!$D20+'Tabla jerseys'!$E20 -> 16.42 | G21: Real Madrid 25-26 Version jugador | H21: VINI JR | I21: XL | J21: 45942 | K21: 32.97 | L21: =K21-F21 -> 16.55
A22: 3 | B22: 45849 | C22: 45881 | D22: 9 | E22: 5.92 | F22: ='Tabla jerseys'!$D22+'Tabla jerseys'!$E22 -> 14.92 | G22: Cruz azul visitante 25/26 | I22: M | J22: 45931 | K22: 27.22 | L22: =K22-F22 -> 12.3
A23: 3 | B23: 45849 | C23: 45881 | D23: 9 | E23: 5.92 | F23: ='Tabla jerseys'!$D23+'Tabla jerseys'!$E23 -> 14.92 | G23: MEXICO | I23: L | J23: 45926 | K23: 26.75 | L23: =K23-F23 -> 11.83
A24: 3 | B24: 45849 | C24: 45872 | D24: 9 | E24: 5.92 | F24: ='Tabla jerseys'!$D30+'Tabla jerseys'!$E30 -> 13.92 | G24: Conjunto FC Barcelona ni–o | H24: Lamine Yamal | I24: 24 | J24: 45893 | K24: 26.78 | L24: =K24-F24 -> 12.86
A25: 3 | B25: 45849 | C25: 45872 | D25: 11 | E25: 5.92 | F25: ='Tabla jerseys'!$D25+'Tabla jerseys'!$E25 -> 16.92 | G25: Conjunto FC Barcelona ni–o | H25: Lamine Yamal | I25: 28 | J25: 45913 | K25: 24.4 | L25: =K25-F25 -> 7.48
A26: 3 | B26: 45849 | C26: 45881 | D26: 9 | E26: 5.92 | F26: ='Tabla jerseys'!$D24+'Tabla jerseys'!$E24 -> 14.92 | G26: FC Barcelona 25-26 version jugador | H26: Lamine Yamal | I26: L | J26: 45914 | K26: 35.25 | L26: =K26-F26 -> 20.33
A27: 3 | B27: 45849 | C27: 45872 | D27: 11 | E27: 5.92 | F27: ='Tabla jerseys'!$D21+'Tabla jerseys'!$E21 -> 17.92 | G27: Conjunto Real Madrid nni–o | H27: MBAPPƒ | I27: 28 | J27: 45936 | K27: 24.46 | L27: =K27-F27 -> 6.54
A28: 3 | B28: 45849 | C28: 45881 | D28: 9 | E28: 5.92 | F28: ='Tabla jerseys'!$D26+'Tabla jerseys'!$E26 -> 14.92 | G28: PSG | I28: L | J28: 45909 | K28: 26.82 | L28: =K28-F28 -> 11.9
A29: 3 | B29: 45849 | C29: 45872 | D29: 8 | E29: 5.92 | F29: ='Tabla jerseys'!$D17+'Tabla jerseys'!$E17 -> 14.92 | G29: Conjunto Chicago bulls | H29: JORDAN | I29: L | J29: 45943 | K29: 21.66 | L29: =K29-F29 -> 6.74
A30: 3 | B30: 45849 | C30: 45872 | D30: 8 | E30: 5.92 | F30: ='Tabla jerseys'!$D18+'Tabla jerseys'!$E18 -> 16.92 | G30: Conjunto Golden state | H30: CURRY | I30: L | J30: 45943 | K30: 21.66 | L30: =K30-F30 -> 4.74
A31: 3 | B31: 45849 | C31: 45872 | D31: 8 | E31: 5.92 | F31: ='Tabla jerseys'!$D19+'Tabla jerseys'!$E19 -> 13.92 | G31: Conjunto Lakers | H31: JAMES | I31: XL | J31: 45943 | K31: 21.66 | L31: =K31-F31 -> 7.74
A32: 3 | B32: 45849 | C32: 45872 | D32: 10.65 | E32: 5.92 | F32: ='Tabla jerseys'!$D45+'Tabla jerseys'!$E45 -> 16.42 | G32: Conjunto inter miami ni–o | H32: MESSI | I32: 22 | J32: 45949 | K32: 21.67 | L32: =K32-F32 -> 5.25
A33: 3 | B33: 45849 | C33: 45872 | D33: 8 | E33: 5.92 | F33: ='Tabla jerseys'!$D41+'Tabla jerseys'!$E41 -> 17.92 | G33: Conjunto Golden state | H33: CURRY | I33: M | J33: 45970 | K33: 21.68 | L33: =K33-F33 -> 3.76
A34: 3 | B34: 45849 | C34: 45881 | D34: 11 | E34: 5.92 | F34: ='Tabla jerseys'!$D27+'Tabla jerseys'!$E27 -> 16.92 | G34: AC Milan 25/26 | H34: GIMENEZ | I34: L | J34: 45906 | K34: 34.88 | L34: =K34-F34 -> 17.96
A35: 3 | B35: 45849 | C35: 45881 | D35: 9 | E35: 5.92 | F35: ='Tabla jerseys'!$D28+'Tabla jerseys'!$E28 -> 14.92 | G35: MEXICO | I35: XL | J35: 45905 | K35: 26.67 | L35: =K35-F35 -> 11.75
A36: 3 | B36: 45849 | C36: 45872 | D36: 11 | E36: 5.92 | F36: ='Tabla jerseys'!$D46+'Tabla jerseys'!$E46 -> 10.5 | G36: Conjunto FC Barcelona ni–o | H36: Lamine Yamal | I36: 26 | J36: 45999 | K36: 22 | L36: =K36-F36 -> 11.5
A37: 3 | B37: 45849 | C37: 45872 | D37: 9 | E37: 5.92 | F37: ='Tabla jerseys'!$D42+'Tabla jerseys'!$E42 -> 13.92 | G37: Conjunto inter miami ni–o | H37: MESSI | I37: 24 | L37: =K37-F37 -> -13.92
A38: 3 | B38: 45849 | C38: 45881 | D38: 12 | E38: 5.92 | F38: ='Tabla jerseys'!$D29+'Tabla jerseys'!$E29 -> 13.92 | G38: Real Madrid 25-26 Version jugador | H38: VINI JR | I38: L | J38: 45899 | K38: 34.84 | L38: =K38-F38 -> 20.92
A39: 3 | B39: 45849 | C39: 45881 | D39: 10 | E39: 5.92 | F39: ='Tabla jerseys'!$D31+'Tabla jerseys'!$E31 -> 13.92 | G39: Real Madrid 25-26 Version jugador | H39: MBAPPƒ | I39: XL | J39: 45890 | K39: 19.54 | L39: =K39-F39 -> 5.62 | P39: =
A40: 3 | B40: 45849 | C40: 45881 | D40: 12 | E40: 5.92 | F40: ='Tabla jerseys'!$D32+'Tabla jerseys'!$E32 -> 16.57 | G40: Real Madrid Alternativa 25-26 Version jugador | H40: MBAPPƒ | I40: L | J40: 45890 | K40: 19.54 | L40: =K40-F40 -> 2.97
...

Sheet power bi
A1: Pedido | B1: Fecha de compra | C1: Fecha llegada | D1: Costo | E1: Costo de envio | F1: Costo total | G1: Modelo | H1: Jugador | I1: Talla | J1: Fecha de venta | K1: Venta | L1: Ganancia
A2: 1 | B2: 45820 | C2: 45841 | D2: 11 | E2: 6 | F2: =Tabla22[[#This Row],[ Costo ]]+E2 -> 17 | G2: FC Barcelona 25-26 Version jugador | H2: LAMINE YAMAL | I2: L | J2: 45841 | K2: 48.19 | L2: =K2-F2 -> 31.19
A3: 1 | B3: 45820 | C3: 45841 | D3: 11 | E3: 6 | F3: =Tabla22[[#This Row],[ Costo ]]+E3 -> 17 | G3: FC Barcelona 25-26 Version jugador | H3: LAMINE YAMAL | I3: L | J3: 45841 | K3: 48.19 | L3: =K3-F3 -> 31.19
A4: 1 | B4: 45820 | C4: 45841 | D4: 10.5 | E4: 6 | F4: =Tabla22[[#This Row],[ Costo ]]+E4 -> 16.5 | G4: Real Madrid 25-26 Version jugador | H4: MBAPPE | I4: L | J4: 45841 | K4: 40 | L4: =K4-F4 -> 23.5
A5: 3 | B5: 45849 | C5: 45881 | D5: 10.5 | E5: 5.92 | F5: =Tabla22[[#This Row],[ Costo ]]+E5 -> 16.42 | G5: America 25-26 Version jugador | H5: HENRY | I5: L | J5: 45882 | K5: 37.67 | L5: =K5-F5 -> 21.25 | N5: Total jerseys | O5: =COUNT('power bi'!$L$2:$L$87) -> 86
A6: 3 | B6: 45849 | C6: 45881 | D6: 10.5 | E6: 5.92 | F6: =Tabla22[[#This Row],[ Costo ]]+E6 -> 16.42 | G6: Inter miami version jugador | H6: Messi | I6: M | J6: 45882 | K6: 37.67 | L6: =K6-F6 -> 21.25 | N6: Jersey Vedidas | O6: =COUNTIF('power bi'!$L$2:$L$87,">0") -> 46
A7: 2 | B7: 45840 | C7: 45860 | D7: 11 | E7: 6 | F7: =Tabla22[[#This Row],[ Costo ]]+E7 -> 17 | G7: FC Barcelona 25-26 Version jugador | H7: LAMINE YAMAL | I7: M | J7: 45862 | K7: 37.63 | L7: =K7-F7 -> 20.63 | N7: Jersey disponible | O7: =COUNTIF('power bi'!$L$2:$L$87,"<0") -> 39
A8: 1 | B8: 45820 | C8: 45841 | D8: 10.5 | E8: 6 | F8: =Tabla22[[#This Row],[ Costo ]]+E8 -> 16.5 | G8: Real Madrid 25-26 Version jugador | H8: MBAPPE | I8: L | J8: 45845 | K8: 37.6 | L8: =K8-F8 -> 21.1 | N8: Total Costo | O8: =SUM('power bi'!$F$2:$F$87) -> 1294.35
A9: 1 | B9: 45820 | C9: 45841 | D9: 10.5 | E9: 6 | F9: =Tabla22[[#This Row],[ Costo ]]+E9 -> 16.5 | G9: FC Barcelona 25-26 Version jugador | H9: PEDRI | I9: L | J9: 45844 | K9: 37.57 | L9: =K9-F9 -> 21.07 | N9: Total venta | O9: =SUM('power bi'!$K$2:$K$87) -> 1453.94
A10: 3 | B10: 45849 | C10: 45881 | D10: 10.5 | E10: 5.92 | F10: =Tabla22[[#This Row],[ Costo ]]+E10 -> 16.42 | G10: America 25-26 Version jugador | H10: HENRY | I10: L | J10: 45882 | K10: 34.98 | L10: =K10-F10 -> 18.56 | N10: Ganancia | O10: =O9-O8 -> 159.59
A11: 7 | D11: 10 | E11: 5.33 | F11: =Tabla22[[#This Row],[ Costo ]]+E11 -> 15.33 | G11: FC Barcelona Travis scott | I11: S | J11: 45930 | K11: 34.84 | L11: =K11-F11 -> 19.51 | N11: Total Costo de disponibles | O11: =SUMIF('power bi'!$L$2:$L$87,"<0",'power bi'!$F$2:$F$87) -> 603.8
A12: 3 | B12: 45849 | C12: 45881 | D12: 12 | E12: 5.92 | F12: =Tabla22[[#This Row],[ Costo ]]+E12 -> 17.92 | G12: Real Madrid 25-26 Version jugador | H12: VINI JR | I12: L | J12: 45899 | K12: 34.84 | L12: =K12-F12 -> 16.92 | N12: Ganancia promedio por jersey vendida | O12: =AVERAGEIF('power bi'!$L$2:$L$87,">0",'power bi'!$L$2:$L$87) -> 16.595435
A13: 4 | B13: 45873 | C13: 45893 | D13: 10.5 | F13: =Tabla22[[#This Row],[ Costo ]]+E13 -> 10.5 | G13: FC Barcelona 25-26 Version jugador | H13: PEDRI | I13: S | J13: 45896 | K13: 34.07 | L13: =K13-F13 -> 23.57 | N13: Ganancia esperada total | O13: =O12*O5 -> 1427.2074
A14: 5 | B14: 45887 | D14: 10.5 | E14: 4.11 | F14: =Tabla22[[#This Row],[ Costo ]]+E14 -> 14.61 | G14: Monterrey mundial version jugador | H14: CANALES | J14: 45930 | K14: 34 | L14: =K14-F14 -> 19.39 | N14: Ganancia por ganar | O14: =O12*O7 -> 647.22196
A15: 7 | D15: 10 | E15: 5.33 | F15: =Tabla22[[#This Row],[ Costo ]]+E15 -> 15.33 | G15: Monterrey visita | H15: Berte | I15: m | J15: 45930 | K15: 33 | L15: =K15-F15 -> 17.67 | N15: Ventas por jersey apartadas | O15: =SUMIF(Tabla22[Fecha de venta],"",Tabla22[Venta]) -> 0
A16: 7 | D16: 10.5 | E16: 5.33 | F16: =Tabla22[[#This Row],[ Costo ]]+E16 -> 15.83 | G16: Monterrey mundial version jugador | H16: Sergio Ramos | I16: m | J16: 45930 | K16: 33 | L16: =K16-F16 -> 17.17 | N16: Ganancia por jersey apartada | O16: =O18+SUMIFS(Tabla22[Ganancia],Tabla22[Ganancia],">0",Tabla22[Fecha de venta],"") -> 0
A17: 7 | D17: 10.5 | E17: 5.33 | F17: =Tabla22[[#This Row],[ Costo ]]+E17 -> 15.83 | G17: Monterrey Local | I17: m | J17: 45930 | K17: 33 | L17: =K17-F17 -> 17.17
A18: 7 | D18: 11.5 | E18: 5.33 | F18: =Tabla22[[#This Row],[ Costo ]]+E18 -> 16.83 | G18: Real Madrid Alternativa 25-26 Version jugador | I18: XL | J18: 45930 | K18: 33 | L18: =K18-F18 -> 16.17
A19: 7 | D19: 11.5 | E19: 5.33 | F19: =Tabla22[[#This Row],[ Costo ]]+E19 -> 16.83 | G19: Real Madrid Alternativa 25-26 Version jugador | I19: XL | J19: 45930 | K19: 33 | L19: =K19-F19 -> 16.17
A20: 7 | D20: 13 | E20: 5.33 | F20: =Tabla22[[#This Row],[ Costo ]]+E20 -> 18.33 | G20: Conjunto Real Madrid nni–o | J20: 45930 | K20: 33 | L20: =K20-F20 -> 14.67
A21: 4 | B21: 45873 | C21: 45893 | D21: 10.5 | E21: 5 | F21: =Tabla22[[#This Row],[ Costo ]]+E21 -> 15.5 | G21: Real Madrid | H21: Mbappe | I21: L | J21: 45895 | K21: 32.29 | L21: =K21-F21 -> 16.79
A22: 4 | B22: 45873 | C22: 45893 | D22: 10.5 | E22: 5.33 | F22: =Tabla22[[#This Row],[ Costo ]]+E22 -> 15.83 | G22: FC Barcelona 25-26 Version jugador | H22: Pedri | I22: L | J22: 45895 | K22: 32.29 | L22: =K22-F22 -> 16.46
A23: 3 | B23: 45849 | C23: 45881 | D23: 10.5 | E23: 5.92 | F23: =Tabla22[[#This Row],[ Costo ]]+E23 -> 16.42 | G23: Conjunto Golden state | H23: CURRY | I23: XL | J23: 45874 | K23: 32.25 | L23: =K23-F23 -> 15.83
A24: 2 | B24: 45840 | C24: 45860 | D24: 10.5 | E24: 6 | F24: =Tabla22[[#This Row],[ Costo ]]+E24 -> 16.5 | G24: FC Barcelona 25-26 Version jugador | H24: LAMINE YAMAL | I24: L | J24: 45875 | K24: 32.25 | L24: =K24-F24 -> 15.75 | Q24: =16.42*3 -> 49.26
A25: 2 | B25: 45840 | C25: 45860 | D25: 10.5 | E25: 6 | F25: =Tabla22[[#This Row],[ Costo ]]+E25 -> 16.5 | G25: FC Barcelona 25-26 Version jugador | H25: LAMINE YAMAL | I25: L | J25: 45873 | K25: 32.25 | L25: =K25-F25 -> 15.75 | P25: =Q25/3 -> 19.543333 | Q25: 58.63
A26: 5 | F26: =Tabla22[[#This Row],[ Costo ]]+E26 -> 0 | G26: FC Barcelona parche | I26: L | J26: 45930 | K26: 32.2 | L26: =K26-F26 -> 32.2 | Q26: =Q25-Q24 -> 9.37
A27: 4 | B27: 45873 | C27: 45893 | D27: 10.5 | E27: 5.33 | F27: =Tabla22[[#This Row],[ Costo ]]+E27 -> 15.83 | G27: FC Barcelona Travis scott | I27: M | J27: 45930 | K27: 32.2 | L27: =K27-F27 -> 16.37
A28: 5 | B28: 45887 | D28: 11 | E28: 5 | F28: =Tabla22[[#This Row],[ Costo ]]+E28 -> 16 | G28: FC Barcelona 25-26 Version jugador | H28: LAMINE YAMAL | I28: 3xl | J28: 45930 | K28: 32.2 | L28: =K28-F28 -> 16.2
A29: 1 | B29: 45820 | C29: 45841 | D29: 10.5 | E29: 6 | F29: =Tabla22[[#This Row],[ Costo ]]+E29 -> 16.5 | G29: Real Madrid 25-26 Version jugador | I29: XL | J29: 45843 | K29: 32.2 | L29: =K29-F29 -> 15.7
A30: 7 | D30: 10 | E30: 5.33 | F30: =Tabla22[[#This Row],[ Costo ]]+E30 -> 15.33 | G30: FC Barcelona Travis scott | I30: L | J30: 45930 | K30: 32.2 | L30: =K30-F30 -> 16.87
A31: 2 | B31: 45840 | C31: 45860 | D31: 11 | E31: 6 | F31: =Tabla22[[#This Row],[ Costo ]]+E31 -> 17 | G31: FC Barcelona 25-26 Version jugador | H31: LAMINE YAMAL | I31: Xl | J31: 45903 | K31: 32.2 | L31: =K31-F31 -> 15.2
A32: 5 | B32: 45887 | D32: 15 | E32: 4.11 | F32: =Tabla22[[#This Row],[ Costo ]]+E32 -> 19.11 | G32: NFL Seahawks | I32: 3XL | J32: 45930 | K32: 31.97 | L32: =K32-F32 -> 12.86
A33: 3 | B33: 45849 | C33: 45872 | D33: 10.5 | E33: $- | G33: Chelsea 2025/26 | H33: Cole Palmer | I33: L | J33: 45877 | K33: 29.62 | L33: =K33-F33 -> 29.62
A34: 1 | B34: 45820 | C34: 45841 | D34: 10.5 | E34: 6 | F34: =Tabla22[[#This Row],[ Costo ]]+E34 -> 16.5 | G34: FC Barcelona 25-26 Version jugador | I34: XL | J34: 45846 | K34: 29.55 | L34: =K34-F34 -> 13.05
A35: 1 | B35: 45820 | C35: 45841 | D35: 10 | E35: 5 | F35: =Tabla22[[#This Row],[ Costo ]]+E35 -> 15 | G35: FC Barcelona 25-26 Version jugador | I35: M | J35: 45853 | K35: 26.87 | L35: =K35-F35 -> 11.87
A36: 1 | B36: 45820 | C36: 45841 | D36: 10.5 | E36: 6 | F36: =Tabla22[[#This Row],[ Costo ]]+E36 -> 16.5 | G36: Real Madrid 25-26 Version jugador | I36: M | J36: 45848 | K36: 26.87 | L36: =K36-F36 -> 10.37
A37: 3 | B37: 45849 | C37: 45872 | D37: 9 | E37: 5.92 | F37: =Tabla22[[#This Row],[ Costo ]]+E37 -> 14.92 | G37: Conjunto FC Barcelona ni–o | H37: Lamine Yamal | I37: 24 | J37: 45893 | K37: 26.78 | L37: =K37-F37 -> 11.86
A38: 7 | D38: 8.5 | E38: 5.33 | F38: =Tabla22[[#This Row],[ Costo ]]+E38 -> 13.83 | G38: MEXICO | J38: 45930 | K38: 26.75 | L38: =K38-F38 -> 12.92
A39: 3 | B39: 45849 | C39: 45881 | D39: 9 | E39: 5.92 | F39: =Tabla22[[#This Row],[ Costo ]]+E39 -> 14.92 | G39: MEXICO | I39: L | J39: 45930 | K39: 26.75 | L39: =K39-F39 -> 11.83 | P39: =
A40: 7 | D40: 10 | E40: 5.33 | F40: =Tabla22[[#This Row],[ Costo ]]+E40 -> 15.33 | G40: MEXICO | J40: 45930 | K40: 26.75 | L40: =K40-F40 -> 11.42
...
